Traceback (most recent call last):
  File "/Users/williamthompson/micromamba/envs/jb-env/lib/python3.11/site-packages/jupyter_cache/executors/utils.py", line 58, in single_nb_execution
    executenb(
  File "/Users/williamthompson/micromamba/envs/jb-env/lib/python3.11/site-packages/nbclient/client.py", line 1314, in execute
    return NotebookClient(nb=nb, resources=resources, km=km, **kwargs).execute()
           ^^^^^^^^^^^^^^^^^^^^^^^^^^^^^^^^^^^^^^^^^^^^^^^^^^^^^^^^^^^^^^^^^^^^^
  File "/Users/williamthompson/micromamba/envs/jb-env/lib/python3.11/site-packages/jupyter_core/utils/__init__.py", line 165, in wrapped
    return loop.run_until_complete(inner)
           ^^^^^^^^^^^^^^^^^^^^^^^^^^^^^^
  File "/Users/williamthompson/micromamba/envs/jb-env/lib/python3.11/asyncio/base_events.py", line 654, in run_until_complete
    return future.result()
           ^^^^^^^^^^^^^^^
  File "/Users/williamthompson/micromamba/envs/jb-env/lib/python3.11/site-packages/nbclient/client.py", line 709, in async_execute
    await self.async_execute_cell(
  File "/Users/williamthompson/micromamba/envs/jb-env/lib/python3.11/site-packages/nbclient/client.py", line 1062, in async_execute_cell
    await self._check_raise_for_error(cell, cell_index, exec_reply)
  File "/Users/williamthompson/micromamba/envs/jb-env/lib/python3.11/site-packages/nbclient/client.py", line 918, in _check_raise_for_error
    raise CellExecutionError.from_cell_and_msg(cell, exec_reply_content)
nbclient.exceptions.CellExecutionError: An error occurred while executing the following cell:
------------------
import os

def show_file_size(path):
    ## get file size in bytes
    file_size = os.path.getsize(path)

    ## convert to human readable format
    units = ['bytes', 'KB', 'MB', 'GB', 'TB']
    for i in range(len(units)):
        if file_size < 1024:
            break
        file_size /= 1024
    print(f'File size: {file_size:.2f} {units[i]}')
    
show_file_size('merged_data.csv')
------------------


[0;31m---------------------------------------------------------------------------[0m
[0;31mFileNotFoundError[0m                         Traceback (most recent call last)
Cell [0;32mIn[1], line 15[0m
[1;32m     12[0m         file_size [38;5;241m/[39m[38;5;241m=[39m [38;5;241m1024[39m
[1;32m     13[0m     [38;5;28mprint[39m([38;5;124mf[39m[38;5;124m'[39m[38;5;124mFile size: [39m[38;5;132;01m{[39;00mfile_size[38;5;132;01m:[39;00m[38;5;124m.2f[39m[38;5;132;01m}[39;00m[38;5;124m [39m[38;5;132;01m{[39;00munits[i][38;5;132;01m}[39;00m[38;5;124m'[39m)
[0;32m---> 15[0m [43mshow_file_size[49m[43m([49m[38;5;124;43m'[39;49m[38;5;124;43mmerged_data.csv[39;49m[38;5;124;43m'[39;49m[43m)[49m

Cell [0;32mIn[1], line 5[0m, in [0;36mshow_file_size[0;34m(path)[0m
[1;32m      3[0m [38;5;28;01mdef[39;00m [38;5;21mshow_file_size[39m(path):
[1;32m      4[0m     [38;5;66;03m## get file size in bytes[39;00m
[0;32m----> 5[0m     file_size [38;5;241m=[39m [43mos[49m[38;5;241;43m.[39;49m[43mpath[49m[38;5;241;43m.[39;49m[43mgetsize[49m[43m([49m[43mpath[49m[43m)[49m
[1;32m      7[0m     [38;5;66;03m## convert to human readable format[39;00m
[1;32m      8[0m     units [38;5;241m=[39m [[38;5;124m'[39m[38;5;124mbytes[39m[38;5;124m'[39m, [38;5;124m'[39m[38;5;124mKB[39m[38;5;124m'[39m, [38;5;124m'[39m[38;5;124mMB[39m[38;5;124m'[39m, [38;5;124m'[39m[38;5;124mGB[39m[38;5;124m'[39m, [38;5;124m'[39m[38;5;124mTB[39m[38;5;124m'[39m]

File [0;32m<frozen genericpath>:50[0m, in [0;36mgetsize[0;34m(filename)[0m

[0;31mFileNotFoundError[0m: [Errno 2] No such file or directory: 'merged_data.csv'

